Workbook
Name 祝日リスト: 祝日一覧!$A:$C

Sheet 出勤簿
A1: 出勤簿
K2: 開始日 | L2: 46033
K4: 締日 | L4: =+YEAR(L2)&"/"&MONTH(L2+30)&"/10" -> 2026/2/10
D6: 出勤① | F6: 出勤② | L6: 日付 | M6: =L4 -> 2026/2/10 | O6: 押印欄
D7: 勤務開始 | E7: 勤務終了 | F7: 勤務開始 | G7: 勤務終了 | L7: 所属部署 | M7: 営業部
D8: 0.27083333 | E8: 0.64583333 | F8: 0.33333333 | G8: 0.70833333 | L8: 氏名 | M8: 池田 和泰 | Q8: ■運転時間確認
A10: 日付 | C10: 区分 | D10: 出勤 時刻 | E10: 退勤 時刻 | F10: 運転 時間 | G10: 荷役 時間 | H10: 休憩 時間 | I10: 実働 時間 | J10: 時間外 労働時間 | K10: 深夜 労働時間 | L10: 早朝 残業 | M10: 遅刻 | N10: 早退 | O10: 備考 | Q10: 平均 (対上行) | R10: 平均 (対下行) | S10: 平均の 下限値 | T10: 判定
A11: =L2 -> 46033 | B11: =L2 -> 46033 | C11: 休日 | G11: =IF(D11="","",I11-F11) | H11: 0.041666667 | I11: =IF(D11="","",E11-D11-H11) | J11: =IF(OR(C11="出勤①",C11="出勤②"), IF(I11<>"",IF(I11-TIME(8,0,0)>TIME(0,1,0),I11-TIME(8,0,0),""),""), IF(OR(C11="法定休日出勤",C11="所定休日出勤"), I11, IF(OR(C11="午前有給",C11="午後有給"), IF(I11<>"",IF(I11-TIME(4,0,0)>TIME(0,1,0),I11-TIME(4,0,0),""),""), "" ) ) ) | L11: =IF(D11="","",IF(D11<TIME(5,0,0),($D$8-D11)-(TIME(5,0,0)-D11),IF(D11>=$D$8,"",$D$8-D11))) | N11: =IF(D11="","",_xlfn.IFS(C11="出勤①",IF(E11<$E$8,$E$8-E11,""),C11="出勤②",IF(E11<$G$8,$G$8-E11,""),TRUE,"")) | Q11: =IF(D11="","",AVERAGE(F11)) | R11: =IF(D11="","",AVERAGE(F11:F12)) | S11: =+MIN(Q11:R11) -> 0 | T11: =+IF(S11>(9/24),"NG","OK") -> OK | AD11: 0.22916667
A12: =IF(A11="","",A11+1) -> 46034 | B12: =IF(B11="","",B11+1) -> 46034 | C12: 休日 | G12: =IF(D12="","",I12-F12) | H12: 0.041666667 | I12: =IF(D12="","",E12-D12-H12) | J12: =IF(OR(C12="出勤①",C12="出勤②"), IF(I12<>"",IF(I12-TIME(8,0,0)>TIME(0,1,0),I12-TIME(8,0,0),""),""), IF(OR(C12="法定休日出勤",C12="所定休日出勤"), I12, IF(OR(C12="午前有給",C12="午後有給"), IF(I12<>"",IF(I12-TIME(4,0,0)>TIME(0,1,0),I12-TIME(4,0,0),""),""), "" ) ) ) | L12: =IF(D12="","",IF(D12<TIME(5,0,0),($D$8-D12)-(TIME(5,0,0)-D12),IF(D12>=$D$8,"",$D$8-D12))) | N12: =IF(D12="","",_xlfn.IFS(C12="出勤①",IF(E12<$E$8,$E$8-E12,""),C12="出勤②",IF(E12<$G$8,$G$8-E12,""),TRUE,"")) | Q12: =IF(D12="","",AVERAGE(F11:F12)) | R12: =IF(D12="","",AVERAGE(F12:F13)) | S12: =+MIN(Q12:R12) -> 0 | T12: =+IF(S12>(9/24),"NG","OK") -> OK | AD12: 0.25
A13: =IF(A12="","",A12+1) -> 46035 | B13: =IF(B12="","",B12+1) -> 46035 | C13: 出勤① | D13: 0.27083333 | E13: 0.70833333 | F13: 0.29166667 | G13: =IF(D13="","",I13-F13) -> 0.10416667 | H13: 0.041666667 | I13: =IF(D13="","",E13-D13-H13) -> 0.39583333 | J13: =IF(OR(C13="出勤①",C13="出勤②"), IF(I13<>"",IF(I13-TIME(8,0,0)>TIME(0,1,0),I13-TIME(8,0,0),""),""), IF(OR(C13="法定休日出勤",C13="所定休日出勤"), I13, IF(OR(C13="午前有給",C13="午後有給"), [1]扶養家族変更届!$J$16 IF(I13<>"",IF(I13-TIME(4,0,0)>TIME(0,1,0),I13-TIME(4,0,0),""),""), "" ) ) ) -> 0.0625 | L13: =IF(D13="","",IF(D13<TIME(5,0,0),($D$8-D13)-(TIME(5,0,0)-D13),IF(D13>=$D$8,"",$D$8-D13))) | N13: =IF(D13="","",_xlfn.IFS(C13="出勤①",IF(E13<$E$8,$E$8-E13,""),C13="出勤②",IF(E13<$G$8,$G$8-E13,""),TRUE,"")) | Q13: =IF(D13="","",AVERAGE(F12:F13)) -> 0.29166667 | R13: =IF(D13="","",AVERAGE(F13:F14)) -> 0.29166667 | S13: =+MIN(Q13:R13) -> 0.29166667 | T13: =+IF(S13>(9/24),"NG","OK") -> OK | AD13: 0.29166667
A14: =IF(A13="","",A13+1) -> 46036 | B14: =IF(B13="","",B13+1) -> 46036 | C14: 出勤① | D14: 0.25 | E14: 0.70833333 | F14: 0.29166667 | G14: =IF(D14="","",I14-F14) -> 0.125 | H14: 0.041666667 | I14: =IF(D14="","",E14-D14-H14) -> 0.41666667 | J14: =IF(OR(C14="出勤①",C14="出勤②"), IF(I14<>"",IF(I14-TIME(8,0,0)>TIME(0,1,0),I14-TIME(8,0,0),""),""), IF(OR(C14="法定休日出勤",C14="所定休日出勤"), I14, IF(OR(C14="午前有給",C14="午後有給"), IF(I14<>"",IF(I14-TIME(4,0,0)>TIME(0,1,0),I14-TIME(4,0,0),""),""), "" ) ) ) -> 0.083333333 | L14: =IF(D14="","",IF(D14<TIME(5,0,0),($D$8-D14)-(TIME(5,0,0)-D14),IF(D14>=$D$8,"",$D$8-D14))) -> 0.020833333 | N14: =IF(D14="","",_xlfn.IFS(C14="出勤①",IF(E14<$E$8,$E$8-E14,""),C14="出勤②",IF(E14<$G$8,$G$8-E14,""),TRUE,"")) | Q14: =IF(D14="","",AVERAGE(F13:F14)) -> 0.29166667 | R14: =IF(D14="","",AVERAGE(F14:F15)) -> 0.30208333 | S14: =+MIN(Q14:R14) -> 0.29166667 | T14: =+IF(S14>(9/24),"NG","OK") -> OK | AD14: 0.3125
A15: =IF(A14="","",A14+1) -> 46037 | B15: =IF(B14="","",B14+1) -> 46037 | C15: 出勤① | D15: 0.27083333 | E15: 0.75 | F15: 0.3125 | G15: =IF(D15="","",I15-F15) -> 0.125 | H15: 0.041666667 | I15: =IF(D15="","",E15-D15-H15) -> 0.4375 | J15: =IF(OR(C15="出勤①",C15="出勤②"), IF(I15<>"",IF(I15-TIME(8,0,0)>TIME(0,1,0),I15-TIME(8,0,0),""),""), IF(OR(C15="法定休日出勤",C15="所定休日出勤"), I15, IF(OR(C15="午前有給",C15="午後有給"), IF(I15<>"",IF(I15-TIME(4,0,0)>TIME(0,1,0),I15-TIME(4,0,0),""),""), "" ) ) ) -> 0.10416667 | L15: =IF(D15="","",IF(D15<TIME(5,0,0),($D$8-D15)-(TIME(5,0,0)-D15),IF(D15>=$D$8,"",$D$8-D15))) | N15: =IF(D15="","",_xlfn.IFS(C15="出勤①",IF(E15<$E$8,$E$8-E15,""),C15="出勤②",IF(E15<$G$8,$G$8-E15,""),TRUE,"")) | Q15: =IF(D15="","",AVERAGE(F14:F15)) -> 0.30208333 | R15: =IF(D15="","",AVERAGE(F15:F16)) -> 0.30208333 | S15: =+MIN(Q15:R15) -> 0.30208333 | T15: =+IF(S15>(9/24),"NG","OK") -> OK | AD15: 0.375
A16: =IF(A15="","",A15+1) -> 46038 | B16: =IF(B15="","",B15+1) -> 46038 | C16: 出勤① | D16: 0.27083333 | E16: 0.72916667 | F16: 0.29166667 | G16: =IF(D16="","",I16-F16) -> 0.125 | H16: 0.041666667 | I16: =IF(D16="","",E16-D16-H16) -> 0.41666667 | J16: =IF(OR(C16="出勤①",C16="出勤②"), IF(I16<>"",IF(I16-TIME(8,0,0)>TIME(0,1,0),I16-TIME(8,0,0),""),""), IF(OR(C16="法定休日出勤",C16="所定休日出勤"), I16, IF(OR(C16="午前有給",C16="午後有給"), IF(I16<>"",IF(I16-TIME(4,0,0)>TIME(0,1,0),I16-TIME(4,0,0),""),""), "" ) ) ) -> 0.083333333 | L16: =IF(D16="","",IF(D16<TIME(5,0,0),($D$8-D16)-(TIME(5,0,0)-D16),IF(D16>=$D$8,"",$D$8-D16))) | N16: =IF(D16="","",_xlfn.IFS(C16="出勤①",IF(E16<$E$8,$E$8-E16,""),C16="出勤②",IF(E16<$G$8,$G$8-E16,""),TRUE,"")) | Q16: =IF(D16="","",AVERAGE(F15:F16)) -> 0.30208333 | R16: =IF(D16="","",AVERAGE(F16:F17)) -> 0.29166667 | S16: =+MIN(Q16:R16) -> 0.29166667 | T16: =+IF(S16>(9/24),"NG","OK") -> OK | AD16: 0.66666667
A17: =IF(A16="","",A16+1) -> 46039 | B17: =IF(B16="","",B16+1) -> 46039 | C17: 休日 | G17: =IF(D17="","",I17-F17) | H17: 0.041666667 | I17: =IF(D17="","",E17-D17-H17) | J17: =IF(OR(C17="出勤①",C17="出勤②"), IF(I17<>"",IF(I17-TIME(8,0,0)>TIME(0,1,0),I17-TIME(8,0,0),""),""), IF(OR(C17="法定休日出勤",C17="所定休日出勤"), I17, IF(OR(C17="午前有給",C17="午後有給"), IF(I17<>"",IF(I17-TIME(4,0,0)>TIME(0,1,0),I17-TIME(4,0,0),""),""), "" ) ) ) | L17: =IF(D17="","",IF(D17<TIME(5,0,0),($D$8-D17)-(TIME(5,0,0)-D17),IF(D17>=$D$8,"",$D$8-D17))) | N17: =IF(D17="","",_xlfn.IFS(C17="出勤①",IF(E17<$E$8,$E$8-E17,""),C17="出勤②",IF(E17<$G$8,$G$8-E17,""),TRUE,"")) | Q17: =IF(D17="","",AVERAGE(F16:F17)) | R17: =IF(D17="","",AVERAGE(F17:F18)) | S17: =+MIN(Q17:R17) -> 0 | T17: =+IF(S17>(9/24),"NG","OK") -> OK | AD17: 0.6875
A18: =IF(A17="","",A17+1) -> 46040 | B18: =IF(B17="","",B17+1) -> 46040 | C18: 休日 | G18: =IF(D18="","",I18-F18) | H18: 0.041666667 | I18: =IF(D18="","",E18-D18-H18) | J18: =IF(OR(C18="出勤①",C18="出勤②"), IF(I18<>"",IF(I18-TIME(8,0,0)>TIME(0,1,0),I18-TIME(8,0,0),""),""), IF(OR(C18="法定休日出勤",C18="所定休日出勤"), I18, IF(OR(C18="午前有給",C18="午後有給"), IF(I18<>"",IF(I18-TIME(4,0,0)>TIME(0,1,0),I18-TIME(4,0,0),""),""), "" ) ) ) | L18: =IF(D18="","",IF(D18<TIME(5,0,0),($D$8-D18)-(TIME(5,0,0)-D18),IF(D18>=$D$8,"",$D$8-D18))) | N18: =IF(D18="","",_xlfn.IFS(C18="出勤①",IF(E18<$E$8,$E$8-E18,""),C18="出勤②",IF(E18<$G$8,$G$8-E18,""),TRUE,"")) | Q18: =IF(D18="","",AVERAGE(F17:F18)) | R18: =IF(D18="","",AVERAGE(F18:F19)) | S18: =+MIN(Q18:R18) -> 0 | T18: =+IF(S18>(9/24),"NG","OK") -> OK | AD18: 0.72916667
A19: =IF(A18="","",A18+1) -> 46041 | B19: =IF(B18="","",B18+1) -> 46041 | C19: 出勤① | D19: 0.25 | E19: 0.6875 | F19: 0.29166667 | G19: =IF(D19="","",I19-F19) -> 0.10416667 | H19: 0.041666667 | I19: =IF(D19="","",E19-D19-H19) -> 0.39583333 | J19: =IF(OR(C19="出勤①",C19="出勤②"), IF(I19<>"",IF(I19-TIME(8,0,0)>TIME(0,1,0),I19-TIME(8,0,0),""),""), IF(OR(C19="法定休日出勤",C19="所定休日出勤"), I19, IF(OR(C19="午前有給",C19="午後有給"), IF(I19<>"",IF(I19-TIME(4,0,0)>TIME(0,1,0),I19-TIME(4,0,0),""),""), "" ) ) ) -> 0.0625 | L19: =IF(D19="","",IF(D19<TIME(5,0,0),($D$8-D19)-(TIME(5,0,0)-D19),IF(D19>=$D$8,"",$D$8-D19))) -> 0.020833333 | N19: =IF(D19="","",_xlfn.IFS(C19="出勤①",IF(E19<$E$8,$E$8-E19,""),C19="出勤②",IF(E19<$G$8,$G$8-E19,""),TRUE,"")) | Q19: =IF(D19="","",AVERAGE(F18:F19)) -> 0.29166667 | R19: =IF(D19="","",AVERAGE(F19:F20)) -> 0.29166667 | S19: =+MIN(Q19:R19) -> 0.29166667 | T19: =+IF(S19>(9/24),"NG","OK") -> OK | AD19: 0.75
A20: =IF(A19="","",A19+1) -> 46042 | B20: =IF(B19="","",B19+1) -> 46042 | C20: 出勤① | D20: 0.25 | E20: 0.70833333 | F20: 0.29166667 | G20: =IF(D20="","",I20-F20) -> 0.125 | H20: 0.041666667 | I20: =IF(D20="","",E20-D20-H20) -> 0.41666667 | J20: =IF(OR(C20="出勤①",C20="出勤②"), IF(I20<>"",IF(I20-TIME(8,0,0)>TIME(0,1,0),I20-TIME(8,0,0),""),""), IF(OR(C20="法定休日出勤",C20="所定休日出勤"), I20, IF(OR(C20="午前有給",C20="午後有給"), IF(I20<>"",IF(I20-TIME(4,0,0)>TIME(0,1,0),I20-TIME(4,0,0),""),""), "" ) ) ) -> 0.083333333 | L20: =IF(D20="","",IF(D20<TIME(5,0,0),($D$8-D20)-(TIME(5,0,0)-D20),IF(D20>=$D$8,"",$D$8-D20))) -> 0.020833333 | N20: =IF(D20="","",_xlfn.IFS(C20="出勤①",IF(E20<$E$8,$E$8-E20,""),C20="出勤②",IF(E20<$G$8,$G$8-E20,""),TRUE,"")) | Q20: =IF(D20="","",AVERAGE(F19:F20)) -> 0.29166667 | R20: =IF(D20="","",AVERAGE(F20:F21)) -> 0.29166667 | S20: =+MIN(Q20:R20) -> 0.29166667 | T20: =+IF(S20>(9/24),"NG","OK") -> OK | AD20: 0.77083333
A21: =IF(A20="","",A20+1) -> 46043 | B21: =IF(B20="","",B20+1) -> 46043 | C21: 出勤① | D21: 0.25 | E21: 0.6875 | F21: 0.29166667 | G21: =IF(D21="","",I21-F21) -> 0.10416667 | H21: 0.041666667 | I21: =IF(D21="","",E21-D21-H21) -> 0.39583333 | J21: =IF(OR(C21="出勤①",C21="出勤②"), IF(I21<>"",IF(I21-TIME(8,0,0)>TIME(0,1,0),I21-TIME(8,0,0),""),""), IF(OR(C21="法定休日出勤",C21="所定休日出勤"), I21, IF(OR(C21="午前有給",C21="午後有給"), IF(I21<>"",IF(I21-TIME(4,0,0)>TIME(0,1,0),I21-TIME(4,0,0),""),""), "" ) ) ) -> 0.0625 | L21: =IF(D21="","",IF(D21<TIME(5,0,0),($D$8-D21)-(TIME(5,0,0)-D21),IF(D21>=$D$8,"",$D$8-D21))) -> 0.020833333 | N21: =IF(D21="","",_xlfn.IFS(C21="出勤①",IF(E21<$E$8,$E$8-E21,""),C21="出勤②",IF(E21<$G$8,$G$8-E21,""),TRUE,"")) | Q21: =IF(D21="","",AVERAGE(F20:F21)) -> 0.29166667 | R21: =IF(D21="","",AVERAGE(F21:F22)) -> 0.29166667 | S21: =+MIN(Q21:R21) -> 0.29166667 | T21: =+IF(S21>(9/24),"NG","OK") -> OK
A22: =IF(A21="","",A21+1) -> 46044 | B22: =IF(B21="","",B21+1) -> 46044 | C22: 出勤① | D22: 0.27083333 | E22: 0.70833333 | F22: 0.29166667 | G22: =IF(D22="","",I22-F22) -> 0.10416667 | H22: 0.041666667 | I22: =IF(D22="","",E22-D22-H22) -> 0.39583333 | J22: =IF(OR(C22="出勤①",C22="出勤②"), IF(I22<>"",IF(I22-TIME(8,0,0)>TIME(0,1,0),I22-TIME(8,0,0),""),""), IF(OR(C22="法定休日出勤",C22="所定休日出勤"), I22, IF(OR(C22="午前有給",C22="午後有給"), IF(I22<>"",IF(I22-TIME(4,0,0)>TIME(0,1,0),I22-TIME(4,0,0),""),""), "" ) ) ) -> 0.0625 | L22: =IF(D22="","",IF(D22<TIME(5,0,0),($D$8-D22)-(TIME(5,0,0)-D22),IF(D22>=$D$8,"",$D$8-D22))) | N22: =IF(D22="","",_xlfn.IFS(C22="出勤①",IF(E22<$E$8,$E$8-E22,""),C22="出勤②",IF(E22<$G$8,$G$8-E22,""),TRUE,"")) | Q22: =IF(D22="","",AVERAGE(F21:F22)) -> 0.29166667 | R22: =IF(D22="","",AVERAGE(F22:F23)) -> 0.28125 | S22: =+MIN(Q22:R22) -> 0.28125 | T22: =+IF(S22>(9/24),"NG","OK") -> OK
A23: =IF(A22="","",A22+1) -> 46045 | B23: =IF(B22="","",B22+1) -> 46045 | C23: 出勤① | D23: 0.27083333 | E23: 0.6875 | F23: 0.27083333 | G23: =IF(D23="","",I23-F23) -> 0.10416667 | H23: 0.041666667 | I23: =IF(D23="","",E23-D23-H23) -> 0.375 | J23: =IF(OR(C23="出勤①",C23="出勤②"), IF(I23<>"",IF(I23-TIME(8,0,0)>TIME(0,1,0),I23-TIME(8,0,0),""),""), IF(OR(C23="法定休日出勤",C23="所定休日出勤"), I23, IF(OR(C23="午前有給",C23="午後有給"), IF(I23<>"",IF(I23-TIME(4,0,0)>TIME(0,1,0),I23-TIME(4,0,0),""),""), "" ) ) ) -> 0.041666667 | L23: =IF(D23="","",IF(D23<TIME(5,0,0),($D$8-D23)-(TIME(5,0,0)-D23),IF(D23>=$D$8,"",$D$8-D23))) | N23: =IF(D23="","",_xlfn.IFS(C23="出勤①",IF(E23<$E$8,$E$8-E23,""),C23="出勤②",IF(E23<$G$8,$G$8-E23,""),TRUE,"")) | Q23: =IF(D23="","",AVERAGE(F22:F23)) -> 0.28125 | R23: =IF(D23="","",AVERAGE(F23:F24)) -> 0.27083333 | S23: =+MIN(Q23:R23) -> 0.27083333 | T23: =+IF(S23>(9/24),"NG","OK") -> OK
A24: =IF(A23="","",A23+1) -> 46046 | B24: =IF(B23="","",B23+1) -> 46046 | C24: 出勤② | D24: 0.33333333 | E24: 0.70833333 | F24: 0.27083333 | G24: =IF(D24="","",I24-F24) -> 0.0625 | H24: 0.041666667 | I24: =IF(D24="","",E24-D24-H24) -> 0.33333333 | J24: =IF(OR(C24="出勤①",C24="出勤②"), IF(I24<>"",IF(I24-TIME(8,0,0)>TIME(0,1,0),I24-TIME(8,0,0),""),""), IF(OR(C24="法定休日出勤",C24="所定休日出勤"), I24, IF(OR(C24="午前有給",C24="午後有給"), IF(I24<>"",IF(I24-TIME(4,0,0)>TIME(0,1,0),I24-TIME(4,0,0),""),""), "" ) ) ) | L24: =IF(D24="","",IF(D24<TIME(5,0,0),($D$8-D24)-(TIME(5,0,0)-D24),IF(D24>=$D$8,"",$D$8-D24))) | N24: =IF(D24="","",_xlfn.IFS(C24="出勤①",IF(E24<$E$8,$E$8-E24,""),C24="出勤②",IF(E24<$G$8,$G$8-E24,""),TRUE,"")) | Q24: =IF(D24="","",AVERAGE(F23:F24)) -> 0.27083333 | R24: =IF(D24="","",AVERAGE(F24:F25)) -> 0.27083333 | S24: =+MIN(Q24:R24) -> 0.27083333 | T24: =+IF(S24>(9/24),"NG","OK") -> OK
A25: =IF(A24="","",A24+1) -> 46047 | B25: =IF(B24="","",B24+1) -> 46047 | C25: 休日 | G25: =IF(D25="","",I25-F25) | H25: 0.041666667 | I25: =IF(D25="","",E25-D25-H25) | J25: =IF(OR(C25="出勤①",C25="出勤②"), IF(I25<>"",IF(I25-TIME(8,0,0)>TIME(0,1,0),I25-TIME(8,0,0),""),""), IF(OR(C25="法定休日出勤",C25="所定休日出勤"), I25, IF(OR(C25="午前有給",C25="午後有給"), IF(I25<>"",IF(I25-TIME(4,0,0)>TIME(0,1,0),I25-TIME(4,0,0),""),""), "" ) ) ) | L25: =IF(D25="","",IF(D25<TIME(5,0,0),($D$8-D25)-(TIME(5,0,0)-D25),IF(D25>=$D$8,"",$D$8-D25))) | N25: =IF(D25="","",_xlfn.IFS(C25="出勤①",IF(E25<$E$8,$E$8-E25,""),C25="出勤②",IF(E25<$G$8,$G$8-E25,""),TRUE,"")) | Q25: =IF(D25="","",AVERAGE(F24:F25)) | R25: =IF(D25="","",AVERAGE(F25:F26)) | S25: =+MIN(Q25:R25) -> 0 | T25: =+IF(S25>(9/24),"NG","OK") -> OK
A26: =IF(A25="","",A25+1) -> 46048 | B26: =IF(B25="","",B25+1) -> 46048 | C26: 出勤① | D26: 0.25 | E26: 0.70833333 | F26: 0.29166667 | G26: =IF(D26="","",I26-F26) -> 0.125 | H26: 0.041666667 | I26: =IF(D26="","",E26-D26-H26) -> 0.41666667 | J26: =IF(OR(C26="出勤①",C26="出勤②"), IF(I26<>"",IF(I26-TIME(8,0,0)>TIME(0,1,0),I26-TIME(8,0,0),""),""), IF(OR(C26="法定休日出勤",C26="所定休日出勤"), I26, IF(OR(C26="午前有給",C26="午後有給"), IF(I26<>"",IF(I26-TIME(4,0,0)>TIME(0,1,0),I26-TIME(4,0,0),""),""), "" ) ) ) -> 0.083333333 | L26: =IF(D26="","",IF(D26<TIME(5,0,0),($D$8-D26)-(TIME(5,0,0)-D26),IF(D26>=$D$8,"",$D$8-D26))) -> 0.020833333 | N26: =IF(D26="","",_xlfn.IFS(C26="出勤①",IF(E26<$E$8,$E$8-E26,""),C26="出勤②",IF(E26<$G$8,$G$8-E26,""),TRUE,"")) | Q26: =IF(D26="","",AVERAGE(F25:F26)) -> 0.29166667 | R26: =IF(D26="","",AVERAGE(F26:F27)) -> 0.29166667 | S26: =+MIN(Q26:R26) -> 0.29166667 | T26: =+IF(S26>(9/24),"NG","OK") -> OK
A27: =IF(A26="","",A26+1) -> 46049 | B27: =IF(B26="","",B26+1) -> 46049 | C27: 出勤① | D27: 0.25 | E27: 0.6875 | F27: 0.29166667 | G27: =IF(D27="","",I27-F27) -> 0.10416667 | H27: 0.041666667 | I27: =IF(D27="","",E27-D27-H27) -> 0.39583333 | J27: =IF(OR(C27="出勤①",C27="出勤②"), IF(I27<>"",IF(I27-TIME(8,0,0)>TIME(0,1,0),I27-TIME(8,0,0),""),""), IF(OR(C27="法定休日出勤",C27="所定休日出勤"), I27, IF(OR(C27="午前有給",C27="午後有給"), IF(I27<>"",IF(I27-TIME(4,0,0)>TIME(0,1,0),I27-TIME(4,0,0),""),""), "" ) ) ) -> 0.0625 | L27: =IF(D27="","",IF(D27<TIME(5,0,0),($D$8-D27)-(TIME(5,0,0)-D27),IF(D27>=$D$8,"",$D$8-D27))) -> 0.020833333 | N27: =IF(D27="","",_xlfn.IFS(C27="出勤①",IF(E27<$E$8,$E$8-E27,""),C27="出勤②",IF(E27<$G$8,$G$8-E27,""),TRUE,"")) | Q27: =IF(D27="","",AVERAGE(F26:F27)) -> 0.29166667 | R27: =IF(D27="","",AVERAGE(F27:F28)) -> 0.29166667 | S27: =+MIN(Q27:R27) -> 0.29166667 | T27: =+IF(S27>(9/24),"NG","OK") -> OK
A28: =IF(A27="","",A27+1) -> 46050 | B28: =IF(B27="","",B27+1) -> 46050 | C28: 出勤① | D28: 0.27083333 | E28: 0.70833333 | F28: 0.29166667 | G28: =IF(D28="","",I28-F28) -> 0.10416667 | H28: 0.041666667 | I28: =IF(D28="","",E28-D28-H28) -> 0.39583333 | J28: =IF(OR(C28="出勤①",C28="出勤②"), IF(I28<>"",IF(I28-TIME(8,0,0)>TIME(0,1,0),I28-TIME(8,0,0),""),""), IF(OR(C28="法定休日出勤",C28="所定休日出勤"), I28, IF(OR(C28="午前有給",C28="午後有給"), IF(I28<>"",IF(I28-TIME(4,0,0)>TIME(0,1,0),I28-TIME(4,0,0),""),""), "" ) ) ) -> 0.0625 | L28: =IF(D28="","",IF(D28<TIME(5,0,0),($D$8-D28)-(TIME(5,0,0)-D28),IF(D28>=$D$8,"",$D$8-D28))) | N28: =IF(D28="","",_xlfn.IFS(C28="出勤①",IF(E28<$E$8,$E$8-E28,""),C28="出勤②",IF(E28<$G$8,$G$8-E28,""),TRUE,"")) | Q28: =IF(D28="","",AVERAGE(F27:F28)) -> 0.29166667 | R28: =IF(D28="","",AVERAGE(F28:F29)) -> 0.28125 | S28: =+MIN(Q28:R28) -> 0.28125 | T28: =+IF(S28>(9/24),"NG","OK") -> OK
A29: =IF(A28="","",A28+1) -> 46051 | B29: =IF(B28="","",B28+1) -> 46051 | C29: 出勤① | D29: 0.27083333 | E29: 0.6875 | F29: 0.27083333 | G29: =IF(D29="","",I29-F29) -> 0.10416667 | H29: 0.041666667 | I29: =IF(D29="","",E29-D29-H29) -> 0.375 | J29: =IF(OR(C29="出勤①",C29="出勤②"), IF(I29<>"",IF(I29-TIME(8,0,0)>TIME(0,1,0),I29-TIME(8,0,0),""),""), IF(OR(C29="法定休日出勤",C29="所定休日出勤"), I29, IF(OR(C29="午前有給",C29="午後有給"), IF(I29<>"",IF(I29-TIME(4,0,0)>TIME(0,1,0),I29-TIME(4,0,0),""),""), "" ) ) ) -> 0.041666667 | L29: =IF(D29="","",IF(D29<TIME(5,0,0),($D$8-D29)-(TIME(5,0,0)-D29),IF(D29>=$D$8,"",$D$8-D29))) | N29: =IF(D29="","",_xlfn.IFS(C29="出勤①",IF(E29<$E$8,$E$8-E29,""),C29="出勤②",IF(E29<$G$8,$G$8-E29,""),TRUE,"")) | Q29: =IF(D29="","",AVERAGE(F28:F29)) -> 0.28125 | R29: =IF(D29="","",AVERAGE(F29:F30)) -> 0.28125 | S29: =+MIN(Q29:R29) -> 0.28125 | T29: =+IF(S29>(9/24),"NG","OK") -> OK
A30: =IF(A29="","",A29+1) -> 46052 | B30: =IF(B29="","",B29+1) -> 46052 | C30: 出勤① | D30: 0.27083333 | E30: 0.70833333 | F30: 0.29166667 | G30: =IF(D30="","",I30-F30) -> 0.10416667 | H30: 0.041666667 | I30: =IF(D30="","",E30-D30-H30) -> 0.39583333 | J30: =IF(OR(C30="出勤①",C30="出勤②"), IF(I30<>"",IF(I30-TIME(8,0,0)>TIME(0,1,0),I30-TIME(8,0,0),""),""), IF(OR(C30="法定休日出勤",C30="所定休日出勤"), I30, IF(OR(C30="午前有給",C30="午後有給"), IF(I30<>"",IF(I30-TIME(4,0,0)>TIME(0,1,0),I30-TIME(4,0,0),""),""), "" ) ) ) -> 0.0625 | L30: =IF(D30="","",IF(D30<TIME(5,0,0),($D$8-D30)-(TIME(5,0,0)-D30),IF(D30>=$D$8,"",$D$8-D30))) | N30: =IF(D30="","",_xlfn.IFS(C30="出勤①",IF(E30<$E$8,$E$8-E30,""),C30="出勤②",IF(E30<$G$8,$G$8-E30,""),TRUE,"")) | Q30: =IF(D30="","",AVERAGE(F29:F30)) -> 0.28125 | R30: =IF(D30="","",AVERAGE(F30:F31)) -> 0.29166667 | S30: =+MIN(Q30:R30) -> 0.28125 | T30: =+IF(S30>(9/24),"NG","OK") -> OK
A31: =IF(A30="","",A30+1) -> 46053 | B31: =IF(B30="","",B30+1) -> 46053 | C31: 休日 | G31: =IF(D31="","",I31-F31) | H31: 0.041666667 | I31: =IF(D31="","",E31-D31-H31) | J31: =IF(OR(C31="出勤①",C31="出勤②"), IF(I31<>"",IF(I31-TIME(8,0,0)>TIME(0,1,0),I31-TIME(8,0,0),""),""), IF(OR(C31="法定休日出勤",C31="所定休日出勤"), I31, IF(OR(C31="午前有給",C31="午後有給"), IF(I31<>"",IF(I31-TIME(4,0,0)>TIME(0,1,0),I31-TIME(4,0,0),""),""), "" ) ) ) | L31: =IF(D31="","",IF(D31<TIME(5,0,0),($D$8-D31)-(TIME(5,0,0)-D31),IF(D31>=$D$8,"",$D$8-D31))) | N31: =IF(D31="","",_xlfn.IFS(C31="出勤①",IF(E31<$E$8,$E$8-E31,""),C31="出勤②",IF(E31<$G$8,$G$8-E31,""),TRUE,"")) | Q31: =IF(D31="","",AVERAGE(F30:F31)) | R31: =IF(D31="","",AVERAGE(F31:F32)) | S31: =+MIN(Q31:R31) -> 0 | T31: =+IF(S31>(9/24),"NG","OK") -> OK
A32: =IF(A31="","",A31+1) -> 46054 | B32: =IF(B31="","",B31+1) -> 46054 | C32: 休日 | G32: =IF(D32="","",I32-F32) | H32: 0.041666667 | I32: =IF(D32="","",E32-D32-H32) | J32: =IF(OR(C32="出勤①",C32="出勤②"), IF(I32<>"",IF(I32-TIME(8,0,0)>TIME(0,1,0),I32-TIME(8,0,0),""),""), IF(OR(C32="法定休日出勤",C32="所定休日出勤"), I32, IF(OR(C32="午前有給",C32="午後有給"), IF(I32<>"",IF(I32-TIME(4,0,0)>TIME(0,1,0),I32-TIME(4,0,0),""),""), "" ) ) ) | L32: =IF(D32="","",IF(D32<TIME(5,0,0),($D$8-D32)-(TIME(5,0,0)-D32),IF(D32>=$D$8,"",$D$8-D32))) | N32: =IF(D32="","",_xlfn.IFS(C32="出勤①",IF(E32<$E$8,$E$8-E32,""),C32="出勤②",IF(E32<$G$8,$G$8-E32,""),TRUE,"")) | Q32: =IF(D32="","",AVERAGE(F31:F32)) | R32: =IF(D32="","",AVERAGE(F32:F33)) | S32: =+MIN(Q32:R32) -> 0 | T32: =+IF(S32>(9/24),"NG","OK") -> OK
A33: =IF(A32="","",A32+1) -> 46055 | B33: =IF(B32="","",B32+1) -> 46055 | C33: 出勤① | D33: 0.27083333 | E33: 0.70833333 | F33: 0.29166667 | G33: =IF(D33="","",I33-F33) -> 0.10416667 | H33: 0.041666667 | I33: =IF(D33="","",E33-D33-H33) -> 0.39583333 | J33: =IF(OR(C33="出勤①",C33="出勤②"), IF(I33<>"",IF(I33-TIME(8,0,0)>TIME(0,1,0),I33-TIME(8,0,0),""),""), IF(OR(C33="法定休日出勤",C33="所定休日出勤"), I33, IF(OR(C33="午前有給",C33="午後有給"), IF(I33<>"",IF(I33-TIME(4,0,0)>TIME(0,1,0),I33-TIME(4,0,0),""),""), "" ) ) ) -> 0.0625 | L33: =IF(D33="","",IF(D33<TIME(5,0,0),($D$8-D33)-(TIME(5,0,0)-D33),IF(D33>=$D$8,"",$D$8-D33))) | N33: =IF(D33="","",_xlfn.IFS(C33="出勤①",IF(E33<$E$8,$E$8-E33,""),C33="出勤②",IF(E33<$G$8,$G$8-E33,""),TRUE,"")) | Q33: =IF(D33="","",AVERAGE(F32:F33)) -> 0.29166667 | R33: =IF(D33="","",AVERAGE(F33:F34)) -> 0.29166667 | S33: =+MIN(Q33:R33) -> 0.29166667 | T33: =+IF(S33>(9/24),"NG","OK") -> OK
A34: =IF(A33="","",A33+1) -> 46056 | B34: =IF(B33="","",B33+1) -> 46056 | C34: 出勤① | D34: 0.27083333 | E34: 0.70833333 | F34: 0.29166667 | G34: =IF(D34="","",I34-F34) -> 0.10416667 | H34: 0.041666667 | I34: =IF(D34="","",E34-D34-H34) -> 0.39583333 | J34: =IF(OR(C34="出勤①",C34="出勤②"), IF(I34<>"",IF(I34-TIME(8,0,0)>TIME(0,1,0),I34-TIME(8,0,0),""),""), IF(OR(C34="法定休日出勤",C34="所定休日出勤"), I34, IF(OR(C34="午前有給",C34="午後有給"), IF(I34<>"",IF(I34-TIME(4,0,0)>TIME(0,1,0),I34-TIME(4,0,0),""),""), "" ) ) ) -> 0.0625 | L34: =IF(D34="","",IF(D34<TIME(5,0,0),($D$8-D34)-(TIME(5,0,0)-D34),IF(D34>=$D$8,"",$D$8-D34))) | N34: =IF(D34="","",_xlfn.IFS(C34="出勤①",IF(E34<$E$8,$E$8-E34,""),C34="出勤②",IF(E34<$G$8,$G$8-E34,""),TRUE,"")) | Q34: =IF(D34="","",AVERAGE(F33:F34)) -> 0.29166667 | R34: =IF(D34="","",AVERAGE(F34:F35)) -> 0.29166667 | S34: =+MIN(Q34:R34) -> 0.29166667 | T34: =+IF(S34>(9/24),"NG","OK") -> OK
A35: =IF(A34="","",A34+1) -> 46057 | B35: =IF(B34="","",B34+1) -> 46057 | C35: 出勤① | D35: 0.25 | E35: 0.6875 | F35: 0.29166667 | G35: =IF(D35="","",I35-F35) -> 0.10416667 | H35: 0.041666667 | I35: =IF(D35="","",E35-D35-H35) -> 0.39583333 | J35: =IF(OR(C35="出勤①",C35="出勤②"), IF(I35<>"",IF(I35-TIME(8,0,0)>TIME(0,1,0),I35-TIME(8,0,0),""),""), IF(OR(C35="法定休日出勤",C35="所定休日出勤"), I35, IF(OR(C35="午前有給",C35="午後有給"), IF(I35<>"",IF(I35-TIME(4,0,0)>TIME(0,1,0),I35-TIME(4,0,0),""),""), "" ) ) ) -> 0.0625 | L35: =IF(D35="","",IF(D35<TIME(5,0,0),($D$8-D35)-(TIME(5,0,0)-D35),IF(D35>=$D$8,"",$D$8-D35))) -> 0.020833333 | N35: =IF(D35="","",_xlfn.IFS(C35="出勤①",IF(E35<$E$8,$E$8-E35,""),C35="出勤②",IF(E35<$G$8,$G$8-E35,""),TRUE,"")) | Q35: =IF(D35="","",AVERAGE(F34:F35)) -> 0.29166667 | R35: =IF(D35="","",AVERAGE(F35:F36)) -> 0.29166667 | S35: =+MIN(Q35:R35) -> 0.29166667 | T35: =+IF(S35>(9/24),"NG","OK") -> OK
A36: =IF(A35="","",A35+1) -> 46058 | B36: =IF(B35="","",B35+1) -> 46058 | C36: 出勤① | D36: 0.25 | E36: 0.70833333 | F36: 0.29166667 | G36: =IF(D36="","",I36-F36) -> 0.125 | H36: 0.041666667 | I36: =IF(D36="","",E36-D36-H36) -> 0.41666667 | J36: =IF(OR(C36="出勤①",C36="出勤②"), IF(I36<>"",IF(I36-TIME(8,0,0)>TIME(0,1,0),I36-TIME(8,0,0),""),""), IF(OR(C36="法定休日出勤",C36="所定休日出勤"), I36, IF(OR(C36="午前有給",C36="午後有給"), IF(I36<>"",IF(I36-TIME(4,0,0)>TIME(0,1,0),I36-TIME(4,0,0),""),""), "" ) ) ) -> 0.083333333 | L36: =IF(D36="","",IF(D36<TIME(5,0,0),($D$8-D36)-(TIME(5,0,0)-D36),IF(D36>=$D$8,"",$D$8-D36))) -> 0.020833333 | N36: =IF(D36="","",_xlfn.IFS(C36="出勤①",IF(E36<$E$8,$E$8-E36,""),C36="出勤②",IF(E36<$G$8,$G$8-E36,""),TRUE,"")) | Q36: =IF(D36="","",AVERAGE(F35:F36)) -> 0.29166667 | R36: =IF(D36="","",AVERAGE(F36:F37)) -> 0.29166667 | S36: =+MIN(Q36:R36) -> 0.29166667 | T36: =+IF(S36>(9/24),"NG","OK") -> OK
A37: =IF(A36="","",A36+1) -> 46059 | B37: =IF(B36="","",B36+1) -> 46059 | C37: 出勤① | D37: 0.25 | E37: 0.6875 | F37: 0.29166667 | G37: =IF(D37="","",I37-F37) -> 0.10416667 | H37: 0.041666667 | I37: =IF(D37="","",E37-D37-H37) -> 0.39583333 | J37: =IF(OR(C37="出勤①",C37="出勤②"), IF(I37<>"",IF(I37-TIME(8,0,0)>TIME(0,1,0),I37-TIME(8,0,0),""),""), IF(OR(C37="法定休日出勤",C37="所定休日出勤"), I37, IF(OR(C37="午前有給",C37="午後有給"), IF(I37<>"",IF(I37-TIME(4,0,0)>TIME(0,1,0),I37-TIME(4,0,0),""),""), "" ) ) ) -> 0.0625 | L37: =IF(D37="","",IF(D37<TIME(5,0,0),($D$8-D37)-(TIME(5,0,0)-D37),IF(D37>=$D$8,"",$D$8-D37))) -> 0.020833333 | N37: =IF(D37="","",_xlfn.IFS(C37="出勤①",IF(E37<$E$8,$E$8-E37,""),C37="出勤②",IF(E37<$G$8,$G$8-E37,""),TRUE,"")) | Q37: =IF(D37="","",AVERAGE(F36:F37)) -> 0.29166667 | R37: =IF(D37="","",AVERAGE(F37:F38)) -> 0.28125 | S37: =+MIN(Q37:R37) -> 0.28125 | T37: =+IF(S37>(9/24),"NG","OK") -> OK
A38: =IF(A37="","",A37+1) -> 46060 | B38: =IF(B37="","",B37+1) -> 46060 | C38: 出勤② | D38: 0.33333333 | E38: 0.70833333 | F38: 0.27083333 | G38: =IF(D38="","",I38-F38) -> 0.0625 | H38: 0.041666667 | I38: =IF(D38="","",E38-D38-H38) -> 0.33333333 | J38: =IF(OR(C38="出勤①",C38="出勤②"), IF(I38<>"",IF(I38-TIME(8,0,0)>TIME(0,1,0),I38-TIME(8,0,0),""),""), IF(OR(C38="法定休日出勤",C38="所定休日出勤"), I38, IF(OR(C38="午前有給",C38="午後有給"), IF(I38<>"",IF(I38-TIME(4,0,0)>TIME(0,1,0),I38-TIME(4,0,0),""),""), "" ) ) ) | K38: {=_xlfn.IFS(I38<>"",IF(AND(D38>TIME(4,59,0),E38<TIME(22,0,1)),"",IF(AND(D38<TIME(5,0,0),E38>TIME(22,0,0)),("5:00"-D38)+(E38-"22:00"),IF(D38<TIME(5,0,0),"5:00"-D38,E38-"22:00"))),TRUE,"")} | L38: =IF(D38="","",IF(D38<TIME(5,0,0),($D$8-D38)-(TIME(5,0,0)-D38),IF(D38>=$D$8,"",$D$8-D38))) | M38: {=IF(D38="","",_xlfn.IFS(C38="出勤①",IF(D38>$D$8,D38-$D$8,""),C38="出勤②",IF(D38>$F$8,D38-$F$8,"")))} | N38: =IF(D38="","",_xlfn.IFS(C38="出勤①",IF(E38<$E$8,$E$8-E38,""),C38="出勤②",IF(E38<$G$8,$G$8-E38,""),TRUE,"")) | Q38: =IF(D38="","",AVERAGE(F37:F38)) -> 0.28125 | R38: =IF(D38="","",AVERAGE(F38:F39)) -> 0.27083333 | S38: =+MIN(Q38:R38) -> 0.27083333 | T38: =+IF(S38>(9/24),"NG","OK") -> OK
A39: =IF(A38="","",A38+1) -> 46061 | B39: =IF(B38="","",B38+1) -> 46061 | C39: 休日 | G39: =IF(D39="","",I39-F39) | H39: 0.041666667 | I39: =IF(D39="","",E39-D39-H39) | J39: =IF(OR(C39="出勤①",C39="出勤②"), IF(I39<>"",IF(I39-TIME(8,0,0)>TIME(0,1,0),I39-TIME(8,0,0),""),""), IF(OR(C39="法定休日出勤",C39="所定休日出勤"), I39, IF(OR(C39="午前有給",C39="午後有給"), IF(I39<>"",IF(I39-TIME(4,0,0)>TIME(0,1,0),I39-TIME(4,0,0),""),""), "" ) ) ) | K39: {=_xlfn.IFS(I39<>"",IF(AND(D39>TIME(4,59,0),E39<TIME(22,0,1)),"",IF(AND(D39<TIME(5,0,0),E39>TIME(22,0,0)),("5:00"-D39)+(E39-"22:00"),IF(D39<TIME(5,0,0),"5:00"-D39,E39-"22:00"))),TRUE,"")} | L39: =IF(D39="","",IF(D39<TIME(5,0,0),($D$8-D39)-(TIME(5,0,0)-D39),IF(D39>=$D$8,"",$D$8-D39))) | M39: {=IF(D39="","",_xlfn.IFS(C39="出勤①",IF(D39>$D$8,D39-$D$8,""),C39="出勤②",IF(D39>$F$8,D39-$F$8,"")))} | N39: =IF(D39="","",_xlfn.IFS(C39="出勤①",IF(E39<$E$8,$E$8-E39,""),C39="出勤②",IF(E39<$G$8,$G$8-E39,""),TRUE,"")) | Q39: =IF(D39="","",AVERAGE(F38:F39)) | R39: =IF(D39="","",AVERAGE(F39:F40)) | S39: =+MIN(Q39:R39) -> 0 | T39: =+IF(S39>(9/24),"NG","OK") -> OK
A40: =IF(A39="","",A39+1) -> 46062 | B40: =IF(B39="","",B39+1) -> 46062 | C40: 出勤① | D40: 0.27083333 | E40: 0.6875 | F40: 0.27083333 | G40: =IF(D40="","",I40-F40) -> 0.10416667 | H40: 0.041666667 | I40: =IF(D40="","",E40-D40-H40) -> 0.375 | J40: =IF(OR(C40="出勤①",C40="出勤②"), IF(I40<>"",IF(I40-TIME(8,0,0)>TIME(0,1,0),I40-TIME(8,0,0),""),""), IF(OR(C40="法定休日出勤",C40="所定休日出勤"), I40, IF(OR(C40="午前有給",C40="午後有給"), IF(I40<>"",IF(I40-TIME(4,0,0)>TIME(0,1,0),I40-TIME(4,0,0),""),""), "" ) ) ) -> 0.041666667 | K40: {=_xlfn.IFS(I40<>"",IF(AND(D40>TIME(4,59,0),E40<TIME(22,0,1)),"",IF(AND(D40<TIME(5,0,0),E40>TIME(22,0,0)),("5:00"-D40)+(E40-"22:00"),IF(D40<TIME(5,0,0),"5:00"-D40,E40-"22:00"))),TRUE,"")} | L40: =IF(D40="","",IF(D40<TIME(5,0,0),($D$8-D40)-(TIME(5,0,0)-D40),IF(D40>=$D$8,"",$D$8-D40))) | M40: {=IF(D40="","",_xlfn.IFS(C40="出勤①",IF(D40>$D$8,D40-$D$8,""),C40="出勤②",IF(D40>$F$8,D40-$F$8,"")))} | N40: =IF(D40="","",_xlfn.IFS(C40="出勤①",IF(E40<$E$8,$E$8-E40,""),C40="出勤②",IF(E40<$G$8,$G$8-E40,""),TRUE,"")) | Q40: =IF(D40="","",AVERAGE(F39:F40)) -> 0.27083333 | R40: =IF(D40="","",AVERAGE(F40:F41)) -> 0.27083333 | S40: =+MIN(Q40:R40) -> 0.27083333 | T40: =+IF(S40>(9/24),"NG","OK") -> OK
A41: =IF(A40="","",A40+1) -> 46063 | B41: =IF(B40="","",B40+1) -> 46063 | C41: 出勤① | D41: 0.27083333 | E41: 0.66666667 | F41: 0.27083333 | G41: =IF(D41="","",I41-F41) -> 0.083333333 | H41: 0.041666667 | I41: =IF(D41="","",E41-D41-H41) -> 0.35416667 | J41: =IF(OR(C41="出勤①",C41="出勤②"), IF(I41<>"",IF(I41-TIME(8,0,0)>TIME(0,1,0),I41-TIME(8,0,0),""),""), IF(OR(C41="法定休日出勤",C41="所定休日出勤"), I41, IF(OR(C41="午前有給",C41="午後有給"), IF(I41<>"",IF(I41-TIME(4,0,0)>TIME(0,1,0),I41-TIME(4,0,0),""),""), "" ) ) ) -> 0.020833333 | K41: {=_xlfn.IFS(I41<>"",IF(AND(D41>TIME(4,59,0),E41<TIME(22,0,1)),"",IF(AND(D41<TIME(5,0,0),E41>TIME(22,0,0)),("5:00"-D41)+(E41-"22:00"),IF(D41<TIME(5,0,0),"5:00"-D41,E41-"22:00"))),TRUE,"")} | L41: =IF(D41="","",IF(D41<TIME(5,0,0),($D$8-D41)-(TIME(5,0,0)-D41),IF(D41>=$D$8,"",$D$8-D41))) | M41: {=IF(D41="","",_xlfn.IFS(C41="出勤①",IF(D41>$D$8,D41-$D$8,""),C41="出勤②",IF(D41>$F$8,D41-$F$8,"")))} | N41: {=IF(D41="","",_xlfn.IFS(C41="出勤①",IF(E41<$E$8,$E$8-E41,""),C41="出勤②",IF(E41<$G$8,$G$8-E41,"")))} | Q41: =IF(D41="","",AVERAGE(F40:F41)) -> 0.27083333 | R41: =IF(D41="","",AVERAGE(F41:F42)) -> 0.27083333 | S41: =+MIN(Q41:R41) -> 0.27083333 | T41: =+IF(S41>(9/24),"NG","OK") -> OK
A42: =IF(A41="","",A41+1) -> 46064 | B42: =IF(B41="","",B41+1) -> 46064 | G42: =IF(D42="","",I42-F42) | H42: 0.041666667 | I42: =IF(D42="","",E42-D42-H42) | J42: {=_xlfn.IFS(I42="","",I42-"8:00">TIME(0,1,0),I42-"8:00",TRUE,"")} | K42: {=_xlfn.IFS(I42<>"",IF(AND(D42>TIME(4,59,0),E42<TIME(22,0,1)),"",IF(AND(D42<TIME(5,0,0),E42>TIME(22,0,0)),("5:00"-D42)+(E42-"22:00"),IF(D42<TIME(5,0,0),"5:00"-D42,E42-"22:00"))),TRUE,"")} | L42: =IF(D42="","",IF(D42<TIME(5,0,0),($D$8-D42)-(TIME(5,0,0)-D42),IF(D42>=$D$8,"",$D$8-D42))) | M42: {=IF(D42="","",_xlfn.IFS(C42="出勤①",IF(D42>$D$8,D42-$D$8,""),C42="出勤②",IF(D42>$F$8,D42-$F$8,"")))} | N42: {=IF(D42="","",_xlfn.IFS(C42="出勤①",IF(E42<$E$8,$E$8-E42,""),C42="出勤②",IF(E42<$G$8,$G$8-E42,"")))} | Q42: =IF(D42="","",AVERAGE(F41:F42)) | R42: =IF(D42="","",AVERAGE(F42:F43)) | S42: =+MIN(Q42:R42) -> 0 | T42: =+IF(S42>(9/24),"NG","OK") -> OK
A43: =IF(A42="","",A42+1) -> 46065 | B43: =IF(B42="","",B42+1) -> 46065 | G43: =IF(D43="","",I43-F43) | H43: 0.041666667 | I43: =IF(D43="","",E43-D43-H43) | J43: {=_xlfn.IFS(I43="","",I43-"8:00">TIME(0,1,0),I43-"8:00",TRUE,"")} | K43: {=_xlfn.IFS(I43<>"",IF(AND(D43>TIME(4,59,0),E43<TIME(22,0,1)),"",IF(AND(D43<TIME(5,0,0),E43>TIME(22,0,0)),("5:00"-D43)+(E43-"22:00"),IF(D43<TIME(5,0,0),"5:00"-D43,E43-"22:00"))),TRUE,"")} | L43: =IF(D43="","",IF(D43<TIME(5,0,0),($D$8-D43)-(TIME(5,0,0)-D43),IF(D43>=$D$8,"",$D$8-D43))) | M43: {=IF(D43="","",_xlfn.IFS(C43="出勤①",IF(D43>$D$8,D43-$D$8,""),C43="出勤②",IF(D43>$F$8,D43-$F$8,"")))} | N43: {=IF(D43="","",_xlfn.IFS(C43="出勤①",IF(E43<$E$8,$E$8-E43,""),C43="出勤②",IF(E43<$G$8,$G$8-E43,"")))} | Q43: =IF(D43="","",AVERAGE(F42:F43)) | R43: =IF(D43="","",AVERAGE(F43:F44)) | S43: =+MIN(Q43:R43) -> 0 | T43: =+IF(S43>(9/24),"NG","OK") -> OK
...

Sheet 関数
A2: =出勤簿!$L$2 -> 46033
A8: 日付 | C8: 祝日
A9: =A2 -> 46033 | B9: =A2 -> 46033 | C9: =IFERROR(VLOOKUP(A9,祝日一覧!$A:$B,2,FALSE),"")
A10: =IF(A9="","",IF(DAY(A9+1)=1,"",A9+1)) -> 46034 | B10: =IF(B9="","",IF(DAY(B9+1)=1,"",B9+1)) -> 46034 | C10: =IFERROR(VLOOKUP(A10,祝日一覧!$A:$B,2,FALSE),"")
A11: =IF(A10="","",IF(DAY(A10+1)=1,"",A10+1)) -> 46035 | B11: =IF(B10="","",IF(DAY(B10+1)=1,"",B10+1)) -> 46035 | C11: =IFERROR(VLOOKUP(A11,祝日一覧!$A:$B,2,FALSE),"")
A12: =IF(A11="","",IF(DAY(A11+1)=1,"",A11+1)) -> 46036 | B12: =IF(B11="","",IF(DAY(B11+1)=1,"",B11+1)) -> 46036 | C12: =IFERROR(VLOOKUP(A12,祝日一覧!$A:$B,2,FALSE),"")
A13: =IF(A12="","",IF(DAY(A12+1)=1,"",A12+1)) -> 46037 | B13: =IF(B12="","",IF(DAY(B12+1)=1,"",B12+1)) -> 46037 | C13: =IFERROR(VLOOKUP(A13,祝日一覧!$A:$B,2,FALSE),"")
A14: =IF(A13="","",IF(DAY(A13+1)=1,"",A13+1)) -> 46038 | B14: =IF(B13="","",IF(DAY(B13+1)=1,"",B13+1)) -> 46038 | C14: =IFERROR(VLOOKUP(A14,祝日一覧!$A:$B,2,FALSE),"")
A15: =IF(A14="","",IF(DAY(A14+1)=1,"",A14+1)) -> 46039 | B15: =IF(B14="","",IF(DAY(B14+1)=1,"",B14+1)) -> 46039 | C15: =IFERROR(VLOOKUP(A15,祝日一覧!$A:$B,2,FALSE),"")
A16: =IF(A15="","",IF(DAY(A15+1)=1,"",A15+1)) -> 46040 | B16: =IF(B15="","",IF(DAY(B15+1)=1,"",B15+1)) -> 46040 | C16: =IFERROR(VLOOKUP(A16,祝日一覧!$A:$B,2,FALSE),"")
A17: =IF(A16="","",IF(DAY(A16+1)=1,"",A16+1)) -> 46041 | B17: =IF(B16="","",IF(DAY(B16+1)=1,"",B16+1)) -> 46041 | C17: =IFERROR(VLOOKUP(A17,祝日一覧!$A:$B,2,FALSE),"")
A18: =IF(A17="","",IF(DAY(A17+1)=1,"",A17+1)) -> 46042 | B18: =IF(B17="","",IF(DAY(B17+1)=1,"",B17+1)) -> 46042 | C18: =IFERROR(VLOOKUP(A18,祝日一覧!$A:$B,2,FALSE),"")
A19: =IF(A18="","",IF(DAY(A18+1)=1,"",A18+1)) -> 46043 | B19: =IF(B18="","",IF(DAY(B18+1)=1,"",B18+1)) -> 46043 | C19: =IFERROR(VLOOKUP(A19,祝日一覧!$A:$B,2,FALSE),"")
A20: =IF(A19="","",IF(DAY(A19+1)=1,"",A19+1)) -> 46044 | B20: =IF(B19="","",IF(DAY(B19+1)=1,"",B19+1)) -> 46044 | C20: =IFERROR(VLOOKUP(A20,祝日一覧!$A:$B,2,FALSE),"")
A21: =IF(A20="","",IF(DAY(A20+1)=1,"",A20+1)) -> 46045 | B21: =IF(B20="","",IF(DAY(B20+1)=1,"",B20+1)) -> 46045 | C21: =IFERROR(VLOOKUP(A21,祝日一覧!$A:$B,2,FALSE),"")
... A39: =IF(A38="","",IF(DAY(A38+1)=1,"",A38+1)) | B39: =IF(B38="","",IF(DAY(B38+1)=1,"",B38+1)) | C39: =IFERROR(VLOOKUP(A39,祝日一覧!$A:$B,2,FALSE),"")

Sheet 祝日一覧
B1: 内閣府HP／「国民の祝日」について | C1: https://www8.cao.go.jp/chosei/shukujitsu/gaiyou.html
B2: 〇令和5年（2023年）の国民の祝日・休日
A3: 日付 | B3: 名称 | C3: 備考
A4: 44927 | B4: 元日
A5: 44928 | B5: 休日 | C5: 祝日法第3条第2項による休日
A6: 44935 | B6: 成人の日
A7: 44968 | B7: 建国記念の日
A8: 44980 | B8: 天皇誕生日
A9: 45006 | B9: 春分の日
A10: 45045 | B10: 昭和の日
A11: 45049 | B11: 憲法記念日
A12: 45050 | B12: みどりの日
A13: 45051 | B13: こどもの日
A14: 45124 | B14: 海の日
A15: 45149 | B15: 山の日
A16: 45187 | B16: 敬老の日
A17: 45192 | B17: 秋分の日
... A20: 45253 | B20: 勤労感謝の日
B22: 〇令和6年（2024年）の国民の祝日・休日
A23: 日付 | B23: 名称 | C23: 備考
A24: 45292 | B24: 元日
A25: 45299 | B25: 成人の日
A26: 45333 | B26: 建国記念の日
A27: 45334 | B27: 休日 | C27: 祝日法第3条第2項による休日
A28: 45345 | B28: 天皇誕生日
A29: 45371 | B29: 春分の日
A30: 45411 | B30: 昭和の日
A31: 45415 | B31: 憲法記念日
A32: 45416 | B32: みどりの日
A33: 45417 | B33: こどもの日
A34: 45418 | B34: 休日 | C34: 祝日法第3条第2項による休日
A35: 45488 | B35: 海の日
A36: 45515 | B36: 山の日
A37: 45516 | B37: 休日 | C37: 祝日法第3条第2項による休日
A38: 45551 | B38: 敬老の日
A39: 45557 | B39: 秋分の日
A40: 45558 | B40: 休日 | C40: 祝日法第3条第2項による休日
A41: 45579 | B41: スポーツの日
A42: 45599 | B42: 文化の日
A43: 45600 | B43: 休日 | C43: 祝日法第3条第2項による休日
...

Sheet 20251021改定内容
H1: 45951
A3: 改定内容
A5: 1.背景
A7: 本社より、ドライバーの人数も増加していることを踏まえ、勤怠集計表に
A8: ドライバーの勤怠情報を追加するよう依頼あり、以下の改定で対応する。
A10: 2.変更内容
A12: 列 | B12: 項目 | C12: 内容
A13: C | B13: 区分 | C13: 「法定休日出勤」「所定労働出勤」を追加
A14: J | B14: 時間外労働時間 | C14: 「法定休日出勤」「所定労働出勤」を追加
A16: 以下 勤怠集計表 転記用項目を追加
H28: 以上
